Workbook
Name Slicer_Category: #N/A
Name Slicer_Product: #N/A
Name Slicer_Region: #N/A
Name Slicer_SalesPerson: #N/A

Sheet Excel_Data_Analytics_Dataset
A1: OrderID | B1: OrderDate | C1: Region | D1: Category | E1: Product | F1: CustomerName | G1: SalesPerson | H1: Sales | I1: Cost | J1: Profit | K1: Profit % | L1: Performance | M1: commision | N1: Cumulative Sales
A2: 1 | B2: 45660 | C2: West | D2: Furniture | E2: Table | F2: Customer_16 | G2: Sneha | H2: 5811 | I2: 5067 | J2: =H2-I2 -> 744 | K2: =J2/H2 -> 0.12803304 | L2: =IF(Excel_Data_Analytics_Dataset!J2>15000,"Excellent",IF(Excel_Data_Analytics_Dataset!J2>=5000,"Good","Poor")) -> Poor | M2: =IF(Table1[[#This Row],[Category]]="Electronics",Excel_Data_Analytics_Dataset!H2*5%,Excel_Data_Analytics_Dataset!H2*8%) -> 464.88 | N2: =SUM(H$2:H2) -> 5811
A3: 2 | B3: 45661 | C3: North | D3: Furniture | E3: Desk | F3: Customer_19 | G3: Sneha | H3: 13553 | I3: 8173 | J3: =H3-I3 -> 5380 | K3: =J3/H3 -> 0.39696008 | L3: =IF(Excel_Data_Analytics_Dataset!J3>15000,"Excellent",IF(Excel_Data_Analytics_Dataset!J3>=5000,"Good","Poor")) -> Good | M3: =IF(Table1[[#This Row],[Category]]="Electronics",Excel_Data_Analytics_Dataset!H3*5%,Excel_Data_Analytics_Dataset!H3*8%) -> 1084.24 | N3: =SUM(H$2:H3) -> 19364
A4: 3 | B4: 45662 | C4: South | D4: Electronics | E4: Mobile | F4: Customer_45 | G4: Sneha | H4: 7987 | I4: 5653 | J4: =H4-I4 -> 2334 | K4: =J4/H4 -> 0.29222487 | L4: =IF(Excel_Data_Analytics_Dataset!J4>15000,"Excellent",IF(Excel_Data_Analytics_Dataset!J4>=5000,"Good","Poor")) -> Poor | M4: =IF(Table1[[#This Row],[Category]]="Electronics",Excel_Data_Analytics_Dataset!H4*5%,Excel_Data_Analytics_Dataset!H4*8%) -> 399.35 | N4: =SUM(H$2:H4) -> 27351
A5: 4 | B5: 45663 | C5: West | D5: Furniture | E5: Chair | F5: Customer_30 | G5: Farhan | H5: 3254 | I5: 2435 | J5: =H5-I5 -> 819 | K5: =J5/H5 -> 0.25169023 | L5: =IF(Excel_Data_Analytics_Dataset!J5>15000,"Excellent",IF(Excel_Data_Analytics_Dataset!J5>=5000,"Good","Poor")) -> Poor | M5: =IF(Table1[[#This Row],[Category]]="Electronics",Excel_Data_Analytics_Dataset!H5*5%,Excel_Data_Analytics_Dataset!H5*8%) -> 260.32 | N5: =SUM(H$2:H5) -> 30605
A6: 5 | B6: 45664 | C6: South | D6: Electronics | E6: Mobile | F6: Customer_40 | G6: Farhan | H6: 13732 | I6: 11076 | J6: =H6-I6 -> 2656 | K6: =J6/H6 -> 0.19341684 | L6: =IF(Excel_Data_Analytics_Dataset!J6>15000,"Excellent",IF(Excel_Data_Analytics_Dataset!J6>=5000,"Good","Poor")) -> Poor | M6: =IF(Table1[[#This Row],[Category]]="Electronics",Excel_Data_Analytics_Dataset!H6*5%,Excel_Data_Analytics_Dataset!H6*8%) -> 686.6 | N6: =SUM(H$2:H6) -> 44337
A7: 6 | B7: 45665 | C7: South | D7: Furniture | E7: Table | F7: Customer_34 | G7: Sneha | H7: 17328 | I7: 14130 | J7: =H7-I7 -> 3198 | K7: =J7/H7 -> 0.18455679 | L7: =IF(Excel_Data_Analytics_Dataset!J7>15000,"Excellent",IF(Excel_Data_Analytics_Dataset!J7>=5000,"Good","Poor")) -> Poor | M7: =IF(Table1[[#This Row],[Category]]="Electronics",Excel_Data_Analytics_Dataset!H7*5%,Excel_Data_Analytics_Dataset!H7*8%) -> 1386.24 | N7: =SUM(H$2:H7) -> 61665
A8: 7 | B8: 45666 | C8: North | D8: Electronics | E8: Laptop | F8: Customer_14 | G8: Aisha | H8: 16650 | I8: 14634 | J8: =H8-I8 -> 2016 | K8: =J8/H8 -> 0.12108108 | L8: =IF(Excel_Data_Analytics_Dataset!J8>15000,"Excellent",IF(Excel_Data_Analytics_Dataset!J8>=5000,"Good","Poor")) -> Poor | M8: =IF(Table1[[#This Row],[Category]]="Electronics",Excel_Data_Analytics_Dataset!H8*5%,Excel_Data_Analytics_Dataset!H8*8%) -> 832.5 | N8: =SUM(H$2:H8) -> 78315
A9: 8 | B9: 45667 | C9: South | D9: Electronics | E9: Headphones | F9: Customer_1 | G9: Sneha | H9: 4964 | I9: 3181 | J9: =H9-I9 -> 1783 | K9: =J9/H9 -> 0.35918614 | L9: =IF(Excel_Data_Analytics_Dataset!J9>15000,"Excellent",IF(Excel_Data_Analytics_Dataset!J9>=5000,"Good","Poor")) -> Poor | M9: =IF(Table1[[#This Row],[Category]]="Electronics",Excel_Data_Analytics_Dataset!H9*5%,Excel_Data_Analytics_Dataset!H9*8%) -> 248.2 | N9: =SUM(H$2:H9) -> 83279
A10: 9 | B10: 45668 | C10: North | D10: Furniture | E10: Table | F10: Customer_49 | G10: Farhan | H10: 19497 | I10: 16208 | J10: =H10-I10 -> 3289 | K10: =J10/H10 -> 0.16869262 | L10: =IF(Excel_Data_Analytics_Dataset!J10>15000,"Excellent",IF(Excel_Data_Analytics_Dataset!J10>=5000,"Good","Poor")) -> Poor | M10: =IF(Table1[[#This Row],[Category]]="Electronics",Excel_Data_Analytics_Dataset!H10*5%,Excel_Data_Analytics_Dataset!H10*8%) -> 1559.76 | N10: =SUM(H$2:H10) -> 102776
A11: 10 | B11: 45669 | C11: South | D11: Electronics | F11: Customer_34 | G11: Rahul | H11: 29094 | I11: 19174 | J11: =H11-I11 -> 9920 | K11: =J11/H11 -> 0.34096377 | L11: =IF(Excel_Data_Analytics_Dataset!J11>15000,"Excellent",IF(Excel_Data_Analytics_Dataset!J11>=5000,"Good","Poor")) -> Good | M11: =IF(Table1[[#This Row],[Category]]="Electronics",Excel_Data_Analytics_Dataset!H11*5%,Excel_Data_Analytics_Dataset!H11*8%) -> 1454.7 | N11: =SUM(H$2:H11) -> 131870
A12: 11 | B12: 45670 | C12: West | D12: Electronics | E12: Mobile | F12: Customer_39 | G12: Nikhil | H12: 27904 | I12: 24463 | J12: =H12-I12 -> 3441 | K12: =J12/H12 -> 0.12331565 | L12: =IF(Excel_Data_Analytics_Dataset!J12>15000,"Excellent",IF(Excel_Data_Analytics_Dataset!J12>=5000,"Good","Poor")) -> Poor | M12: =IF(Table1[[#This Row],[Category]]="Electronics",Excel_Data_Analytics_Dataset!H12*5%,Excel_Data_Analytics_Dataset!H12*8%) -> 1395.2 | N12: =SUM(H$2:H12) -> 159774
A13: 12 | B13: 45671 | C13: North | D13: Electronics | E13: Headphones | F13: Customer_23 | G13: Aisha | H13: 9233 | I13: 6766 | J13: =H13-I13 -> 2467 | K13: =J13/H13 -> 0.26719376 | L13: =IF(Excel_Data_Analytics_Dataset!J13>15000,"Excellent",IF(Excel_Data_Analytics_Dataset!J13>=5000,"Good","Poor")) -> Poor | M13: =IF(Table1[[#This Row],[Category]]="Electronics",Excel_Data_Analytics_Dataset!H13*5%,Excel_Data_Analytics_Dataset!H13*8%) -> 461.65 | N13: =SUM(H$2:H13) -> 169007
A14: 13 | B14: 45672 | C14: East | D14: Furniture | E14: Desk | F14: Customer_38 | G14: Sneha | H14: 27329 | I14: 18038 | J14: =H14-I14 -> 9291 | K14: =J14/H14 -> 0.33996853 | L14: =IF(Excel_Data_Analytics_Dataset!J14>15000,"Excellent",IF(Excel_Data_Analytics_Dataset!J14>=5000,"Good","Poor")) -> Good | M14: =IF(Table1[[#This Row],[Category]]="Electronics",Excel_Data_Analytics_Dataset!H14*5%,Excel_Data_Analytics_Dataset!H14*8%) -> 2186.32 | N14: =SUM(H$2:H14) -> 196336
A15: 14 | B15: 45673 | C15: West | D15: Furniture | E15: Desk | F15: Customer_5 | G15: Rahul | H15: 6994 | I15: 5062 | J15: =H15-I15 -> 1932 | K15: =J15/H15 -> 0.27623677 | L15: =IF(Excel_Data_Analytics_Dataset!J15>15000,"Excellent",IF(Excel_Data_Analytics_Dataset!J15>=5000,"Good","Poor")) -> Poor | M15: =IF(Table1[[#This Row],[Category]]="Electronics",Excel_Data_Analytics_Dataset!H15*5%,Excel_Data_Analytics_Dataset!H15*8%) -> 559.52 | N15: =SUM(H$2:H15) -> 203330
A16: 15 | B16: 45674 | C16: East | D16: Furniture | E16: Table | F16: Customer_4 | G16: Sneha | H16: 6822 | I16: 5407 | J16: =H16-I16 -> 1415 | K16: =J16/H16 -> 0.20741718 | L16: =IF(Excel_Data_Analytics_Dataset!J16>15000,"Excellent",IF(Excel_Data_Analytics_Dataset!J16>=5000,"Good","Poor")) -> Poor | M16: =IF(Table1[[#This Row],[Category]]="Electronics",Excel_Data_Analytics_Dataset!H16*5%,Excel_Data_Analytics_Dataset!H16*8%) -> 545.76 | N16: =SUM(H$2:H16) -> 210152
A17: 16 | B17: 45675 | C17: East | D17: Electronics | E17: Headphones | F17: Customer_39 | G17: Farhan | H17: 14681 | I17: 11778 | J17: =H17-I17 -> 2903 | K17: =J17/H17 -> 0.19773857 | L17: =IF(Excel_Data_Analytics_Dataset!J17>15000,"Excellent",IF(Excel_Data_Analytics_Dataset!J17>=5000,"Good","Poor")) -> Poor | M17: =IF(Table1[[#This Row],[Category]]="Electronics",Excel_Data_Analytics_Dataset!H17*5%,Excel_Data_Analytics_Dataset!H17*8%) -> 734.05 | N17: =SUM(H$2:H17) -> 224833
A18: 17 | B18: 45676 | C18: West | D18: Electronics | E18: Laptop | F18: Customer_10 | G18: Aisha | H18: 21800 | I18: 16672 | J18: =H18-I18 -> 5128 | K18: =J18/H18 -> 0.23522936 | L18: =IF(Excel_Data_Analytics_Dataset!J18>15000,"Excellent",IF(Excel_Data_Analytics_Dataset!J18>=5000,"Good","Poor")) -> Good | M18: =IF(Table1[[#This Row],[Category]]="Electronics",Excel_Data_Analytics_Dataset!H18*5%,Excel_Data_Analytics_Dataset!H18*8%) -> 1090 | N18: =SUM(H$2:H18) -> 246633
A19: 18 | B19: 45677 | C19: East | D19: Electronics | E19: Headphones | F19: Customer_23 | G19: Nikhil | H19: 27543 | I19: 21241 | J19: =H19-I19 -> 6302 | K19: =J19/H19 -> 0.22880587 | L19: =IF(Excel_Data_Analytics_Dataset!J19>15000,"Excellent",IF(Excel_Data_Analytics_Dataset!J19>=5000,"Good","Poor")) -> Good | M19: =IF(Table1[[#This Row],[Category]]="Electronics",Excel_Data_Analytics_Dataset!H19*5%,Excel_Data_Analytics_Dataset!H19*8%) -> 1377.15 | N19: =SUM(H$2:H19) -> 274176
A20: 19 | B20: 45678 | C20: South | D20: Furniture | E20: Cupboard | F20: Customer_45 | G20: Aisha | H20: 8177 | I20: 6277 | J20: =H20-I20 -> 1900 | K20: =J20/H20 -> 0.23235906 | L20: =IF(Excel_Data_Analytics_Dataset!J20>15000,"Excellent",IF(Excel_Data_Analytics_Dataset!J20>=5000,"Good","Poor")) -> Poor | M20: =IF(Table1[[#This Row],[Category]]="Electronics",Excel_Data_Analytics_Dataset!H20*5%,Excel_Data_Analytics_Dataset!H20*8%) -> 654.16 | N20: =SUM(H$2:H20) -> 282353
A21: 20 | B21: 45679 | C21: North | D21: Electronics | E21: Tablet | F21: Customer_22 | G21: Rahul | H21: 17261 | I21: 14516 | J21: =H21-I21 -> 2745 | K21: =J21/H21 -> 0.15902902 | L21: =IF(Excel_Data_Analytics_Dataset!J21>15000,"Excellent",IF(Excel_Data_Analytics_Dataset!J21>=5000,"Good","Poor")) -> Poor | M21: =IF(Table1[[#This Row],[Category]]="Electronics",Excel_Data_Analytics_Dataset!H21*5%,Excel_Data_Analytics_Dataset!H21*8%) -> 863.05 | N21: =SUM(H$2:H21) -> 299614
A22: 21 | B22: 45680 | C22: East | D22: Electronics | E22: Laptop | F22: Customer_25 | G22: Aisha | H22: 13080 | I22: 11394 | J22: =H22-I22 -> 1686 | K22: =J22/H22 -> 0.12889908 | L22: =IF(Excel_Data_Analytics_Dataset!J22>15000,"Excellent",IF(Excel_Data_Analytics_Dataset!J22>=5000,"Good","Poor")) -> Poor | M22: =IF(Table1[[#This Row],[Category]]="Electronics",Excel_Data_Analytics_Dataset!H22*5%,Excel_Data_Analytics_Dataset!H22*8%) -> 654 | N22: =SUM(H$2:H22) -> 312694
A23: 22 | B23: 45681 | C23: West | D23: Furniture | E23: Desk | F23: Customer_31 | G23: Rahul | H23: 12676 | I23: 8182 | J23: =H23-I23 -> 4494 | K23: =J23/H23 -> 0.35452824 | L23: =IF(Excel_Data_Analytics_Dataset!J23>15000,"Excellent",IF(Excel_Data_Analytics_Dataset!J23>=5000,"Good","Poor")) -> Poor | M23: =IF(Table1[[#This Row],[Category]]="Electronics",Excel_Data_Analytics_Dataset!H23*5%,Excel_Data_Analytics_Dataset!H23*8%) -> 1014.08 | N23: =SUM(H$2:H23) -> 325370
... A201: 200 | B201: 45859 | C201: East | D201: Electronics | E201: Headphones | F201: Customer_22 | G201: Nikhil | H201: 6437 | I201: 4292 | J201: =H201-I201 -> 2145 | K201: =J201/H201 -> 0.33322977 | L201: =IF(Excel_Data_Analytics_Dataset!J201>15000,"Excellent",IF(Excel_Data_Analytics_Dataset!J201>=5000,"Good","Poor")) -> Poor | M201: =IF(Table1[[#This Row],[Category]]="Electronics",Excel_Data_Analytics_Dataset!H201*5%,Excel_Data_Analytics_Dataset!H201*8%) -> 321.85 | N201: =SUM(H$2:H201) -> 3235200

Sheet  Employee_Salary
A1: Name | B1: Salary | C1: Total Sales | D1: Rank
A2: Aisha | B2: 45000 | C2: =SUMIF(Excel_Data_Analytics_Dataset!G$2:G$201, A2, Excel_Data_Analytics_Dataset!H$2:H$201) -> 750452 | D2: =_xlfn.RANK.EQ(C2,C$2:C$6) -> 1
A3: Rahul | B3: 42000 | C3: =SUMIF(Excel_Data_Analytics_Dataset!G$2:G$201, A3, Excel_Data_Analytics_Dataset!H$2:H$201) -> 633574 | D3: =_xlfn.RANK.EQ(C3,C$2:C$6) -> 4
A4: Nikhil | B4: 40000 | C4: =SUMIF(Excel_Data_Analytics_Dataset!G$2:G$201, A4, Excel_Data_Analytics_Dataset!H$2:H$201) -> 648534 | D4: =_xlfn.RANK.EQ(C4,C$2:C$6) -> 3
A5: Sneha | B5: 47000 | C5: =SUMIF(Excel_Data_Analytics_Dataset!G$2:G$201, A5, Excel_Data_Analytics_Dataset!H$2:H$201) -> 509237 | D5: =_xlfn.RANK.EQ(C5,C$2:C$6) -> 5
A6: Farhan | B6: 43000 | C6: =SUMIF(Excel_Data_Analytics_Dataset!G$2:G$201, A6, Excel_Data_Analytics_Dataset!H$2:H$201) -> 693403 | D6: =_xlfn.RANK.EQ(C6,C$2:C$6) -> 2

Sheet Answers
A1: Section A – Data Cleaning
A2: 1.Format OrderDate as Date format.
A3: =DATE(2025,1,2) -> 45659 | B3: Date format ok
A4: 2.Remove duplicate records (if any).
A5: Click anywhere inside your data range. Go to the Data tab -> Data Tools group-> Click Remove Duplicates. Ensure all column checkboxes are selected and click OK.
A6: 3.Remove extra spaces in text fields.
A7: =TRIM(Excel_Data_Analytics_Dataset!F8) -> Customer_14 | B7: =_xlfn.FORMULATEXT(A7) -> =TRIM(Excel_Data_Analytics_Dataset!F8)
A8: 4.Convert the dataset into an Excel Table (Ctrl + T).
A9: Done
A12: Section B – Basic Calculations
A13: 7.Calculate:
A14: Column1 | B14: Column2
A15: • Total Sales | B15: =SUM(Excel_Data_Analytics_Dataset!H2:H201) -> 3235200
A16: • Total Cost | B16: =SUM(Excel_Data_Analytics_Dataset!I2:I201) -> 2447134
A17: • Total Profit | B17: =SUM(Excel_Data_Analytics_Dataset!J2:J201) -> 788066
A18: • Total Orders | B18: =COUNT(Excel_Data_Analytics_Dataset!A2:A201) -> 200
A19: 8.Average Sales per Order
A20: Average sales per Order | B20: =AVERAGE(B15/B18) -> 16176
A22: Section C – Functions Practice
A23: 9.Count orders from North region.
A24: Orders from North Region | B24: =COUNTIF(Excel_Data_Analytics_Dataset!C2:C201,"North") -> 42
A26: 10.Count Electronics category orders.
A27: Electronics category orders | B27: =COUNTIF(Excel_Data_Analytics_Dataset!D2:D201,"Electronics") -> 96
A28: 11.Find Maximum, Minimum, and Average sales.
A29: Maximum Sales | B29: =MAX(Excel_Data_Analytics_Dataset!H2:H201) -> 29811
A30: Minimum Sales | B30: =MIN(Excel_Data_Analytics_Dataset!H2:H201) -> 3003
A31: Average Sales | B31: =AVERAGE(Excel_Data_Analytics_Dataset!H2:H201) -> 16176
A32: 12.Use IF/IFS:
A34: • Profit > 15000 → Excellent
A35: • 5000–15000 → Good • Else → Poor | C35: =IF(Excel_Data_Analytics_Dataset!J3>15000,"Excellent",IF(Excel_Data_Analytics_Dataset!J2>=5000,"Good","Poor")) -> Poor
A37: Section D – Lookup & Logical
A39: 13.Fetch Salary from Employee_Salary sheet using VLOOKUP/XLOOKUP.
A40: VLOOKUP | B40: =VLOOKUP("Aisha",' Employee_Salary'!A2:B6,2,TRUE) -> 45000 | C40: =_xlfn.FORMULATEXT(B40) -> =VLOOKUP("Aisha",' Employee_Salary'!A2:B6,2,TRUE)
A41: 14. Salary-to-Sales Ratio
A42: salary to sales ratio | B42: =' Employee_Salary'!B2/Excel_Data_Analytics_Dataset!H20 -> 5.5032408 | C42: =_xlfn.FORMULATEXT(B42) -> =' Employee_Salary'!B2/Excel_Data_Analytics_Dataset!H20
A43: 15.Calculate Commission:
A44: Electronics → 5% • Furniture→ 8% | C44: =IF(Excel_Data_Analytics_Dataset!D2:D201="Electronics",Excel_Data_Analytics_Dataset!H2*5%,Excel_Data_Analytics_Dataset!H2*8%) -> 290.55
A45: 16. Rank SalesPerson Based on Total Sales
A47: Section E – Advanced Formulas
A49: 17.Create Running Total (Cumulative Sales) by date
...

Sheet PivotTableSectionG
A1: 24. Region/Sales | D1: 25.Product/Profit | G1: 26.SalesPerson/Sales | J1: 27.Monthly Sales summary
A3: Row Labels | B3: Sum of Sales | D3: Row Labels | E3: Sum of Profit | G3: Row Labels | H3: Sum of Sales | J3: Row Labels | K3: Sum of Sales
A4: West | B4: 881864 | D4: Desk | E4: 116163 | G4: Aisha | H4: 750452 | J4: Jan | K4: 458875
A5: South | B5: 866015 | D5: Laptop | E5: 110535 | G5: Farhan | H5: 693403 | J5: Feb | K5: 466579
A6: East | B6: 788936 | D6: Tablet | E6: 104776 | G6: Nikhil | H6: 648534 | J6: Mar | K6: 534382
A7: North | B7: 698385 | D7: Mobile | E7: 99690 | G7: Rahul | H7: 633574 | J7: Apr | K7: 468761
A8: Grand Total | B8: 3235200 | D8: Cupboard | E8: 96237 | G8: Sneha | H8: 509237 | J8: May | K8: 545139
D9: Headphones | E9: 95108 | G9: Grand Total | H9: 3235200 | J9: Jun | K9: 456613
A10: =GETPIVOTDATA("Sales",$A$3) -> 3235200 | D10: Table | E10: 89706 | J10: Jul | K10: 304851
A11: =GETPIVOTDATA("Profit",$D$3) -> 788066 | D11: Chair | E11: 75851 | J11: Grand Total | K11: 3235200
D12: Grand Total | E12: 788066
A15: 28.Show % of Grand Total in Pivot. | G15: Category/Sales | J15: Line chart → Daily sales trend.
A17: Row Labels | B17: Sum of Profit | G17: Row Labels | H17: Sum of Sales | J17: Row Labels | K17: Sum of Sales
A18: Chair | B18: 0.096249553 | G18: Electronics | H18: 1638383 | J18: 03-Jan | K18: 5811
A19: Cupboard | B19: 0.12211794 | G19: Furniture | H19: 1596817 | J19: 04-Jan | K19: 13553
A20: Desk | B20: 0.14740263 | G20: Grand Total | H20: 3235200 | J20: 05-Jan | K20: 7987
A21: Headphones | B21: 0.12068532 | J21: 06-Jan | K21: 3254
A22: Laptop | B22: 0.14026109 | J22: 07-Jan | K22: 13732
A23: Mobile | B23: 0.12649956 | J23: 08-Jan | K23: 17328
A24: Table | B24: 0.11383057 | J24: 09-Jan | K24: 16650
A25: Tablet | B25: 0.13295333 | J25: 10-Jan | K25: 4964
A26: Grand Total | B26: 1 | J26: 11-Jan | K26: 19497
J27: 12-Jan | K27: 29094
J28: 13-Jan | K28: 27904
J29: 14-Jan | K29: 9233
J30: 15-Jan | K30: 27329
A31: Sales person Rank | E31: Total | J31: 16-Jan | K31: 6994
J32: 17-Jan | K32: 6822
A33: Row Labels | B33: Sum of Rank | E33: Row Labels | F33: Sum of Column2 | J33: 18-Jan | K33: 14681
A34: Aisha | B34: 1 | E34: • Total Cost | F34: 2447134 | J34: 19-Jan | K34: 21800
A35: Farhan | B35: 2 | E35: • Total Orders | F35: 200 | G35: =GETPIVOTDATA("Column2",$E$33,"Column1","• Total Orders") -> 200 | J35: 20-Jan | K35: 27543
A36: Nikhil | B36: 3 | E36: • Total Profit | F36: 788066 | J36: 21-Jan | K36: 8177
A37: Rahul | B37: 4 | E37: • Total Sales | F37: 3235200 | J37: 22-Jan | K37: 17261
A38: Sneha | B38: 5 | J38: 23-Jan | K38: 13080
J39: 24-Jan | K39: 12676
J40: 25-Jan | K40: 12995
A41: Row Labels | B41: Sum of Sales | E41: Count of OrderID | J41: 26-Jan | K41: 26402
A42: Aisha | B42: 750452 | E42: 200 | F42: =GETPIVOTDATA("OrderID",$E$41) -> 200 | J42: 27-Jan | K42: 20499
A43: Farhan | B43: 693403 | J43: 28-Jan | K43: 22507
A44: Nikhil | B44: 648534 | J44: 29-Jan | K44: 4786
...

Sheet Section H – Charts
A1: 29.Column chart → Region vs Sales. | H1: 30.Pie chart → Category share. | P1: 31.Line chart → Daily sales trend.
A20: 32.Bar chart → SalesPerson ranking. | I20: Month Sales | Q20: Product Profit

Sheet Section I – Dashboard

Sheet DashBoard

Sheet 5businessinsights
A2: Write 5 business insights from your dashboard (performance, trends, and recommendations).
A3: 1. West Region has the highest sales.
A4: The West region performs better than the other regions.
A5: Suggestion: Use the same sales methods in other regions.
A6: 2. Aisha is the best salesperson.
A7: She has achieved the highest sales.
A8: Suggestion: Reward her and learn from her sales techniques.
A9: 3. Electronics and Furniture sell almost equally.
A10: Both categories contribute nearly the same amount of sales.
A11: Suggestion: Continue focusing on both product categories.
A12: 4. Sales were highest in May.
A13: Sales increased until May and then started to decrease.
... A23: in lower-performing months and regions.
